<?xml version="1.0"?>
<robot xmlns:xacro="http://www.ros.org/wiki/xacro" name="ackermann_robot">

  <!-- ==================== Constants ==================== -->
  <xacro:property name="PI" value="3.1415926535897931"/>
  <xacro:property name="wheelbase" value="0.45"/>
  <xacro:property name="track_width" value="0.35"/>
  <xacro:property name="wheel_radius" value="0.07"/>
  <xacro:property name="wheel_diameter" value="0.14"/>
  <xacro:property name="wheel_width" value="0.04"/>
  <xacro:property name="chassis_length" value="0.55"/>
  <xacro:property name="chassis_width" value="0.38"/>
  <xacro:property name="chassis_height" value="0.12"/>
  <xacro:property name="lidar_height" value="0.25"/>

  <!-- ==================== Base Link ==================== -->
  <link name="base_footprint"/>

  <joint name="base_footprint_joint" type="fixed">
    <parent link="base_footprint"/>
    <child link="base_link"/>
    <origin xyz="0 0 ${wheel_radius}" rpy="0 0 0"/>
  </joint>

  <link name="base_link">
    <inertial>
      <mass value="15.0"/>
      <inertia ixx="0.5" ixy="0" ixz="0" iyy="0.5" iyz="0" izz="0.5"/>
    </inertial>
    <visual name="base_visual">
      <geometry>
        <box size="${chassis_length} ${chassis_width} ${chassis_height}"/>
      </geometry>
      <material name="blue">
        <color rgba="0.2 0.4 0.8 1.0"/>
      </material>
    </visual>
    <collision name="base_collision">
      <geometry>
        <box size="${chassis_length} ${chassis_width} ${chassis_height}"/>
      </geometry>
      <surface>
        <friction>
          <ode>
            <mu>0.8</mu>
            <mu2>0.8</mu2>
          </ode>
        </friction>
      </surface>
    </collision>
  </link>

  <!-- ==================== Front Steering Joints ==================== -->
  <joint name="left_steering_joint" type="revolute">
    <parent link="base_link"/>
    <child link="left_steering_link"/>
    <origin xyz="${wheelbase/2} ${track_width/2} 0" rpy="0 0 0"/>
    <axis xyz="0 0 1"/>
    <limit lower="-0.6" upper="0.6" effort="100" velocity="10"/>
    <dynamics damping="0.1" friction="0.1"/>
  </joint>
  <link name="left_steering_link">
    <inertial>
      <mass value="0.01"/>
      <inertia ixx="0.001" ixy="0" ixz="0" iyy="0.001" iyz="0" izz="0.001"/>
    </inertial>
  </link>

  <joint name="right_steering_joint" type="revolute">
    <parent link="base_link"/>
    <child link="right_steering_link"/>
    <origin xyz="${wheelbase/2} ${-track_width/2} 0" rpy="0 0 0"/>
    <axis xyz="0 0 1"/>
    <limit lower="-0.6" upper="0.6" effort="100" velocity="10"/>
    <dynamics damping="0.1" friction="0.1"/>
  </joint>
  <link name="right_steering_link">
    <inertial>
      <mass value="0.01"/>
      <inertia ixx="0.001" ixy="0" ixz="0" iyy="0.001" iyz="0" izz="0.001"/>
    </inertial>
  </link>

  <joint name="steering_wheel_joint" type="continuous">
    <parent link="base_link"/>
    <child link="steering_wheel_link"/>
    <origin xyz="0.12 0 0.12" rpy="0 0 0"/>
    <axis xyz="0 0 1"/>
    <dynamics damping="0.1" friction="0.1"/>
  </joint>
  <link name="steering_wheel_link">
    <inertial>
      <mass value="0.01"/>
      <inertia ixx="0.0001" ixy="0" ixz="0" iyy="0.0001" iyz="0" izz="0.0001"/>
    </inertial>
  </link>

  <!-- ==================== Rear Fixed Joints ==================== -->
  <joint name="rear_left_fixed_joint" type="fixed">
    <parent link="base_link"/>
    <child link="rear_left_fixed_link"/>
    <origin xyz="${-wheelbase/2} ${track_width/2} 0" rpy="0 0 0"/>
  </joint>
  <link name="rear_left_fixed_link">
    <inertial>
      <mass value="0.01"/>
      <inertia ixx="0.001" ixy="0" ixz="0" iyy="0.001" iyz="0" izz="0.001"/>
    </inertial>
  </link>

  <joint name="rear_right_fixed_joint" type="fixed">
    <parent link="base_link"/>
    <child link="rear_right_fixed_link"/>
    <origin xyz="${-wheelbase/2} ${-track_width/2} 0" rpy="0 0 0"/>
  </joint>
  <link name="rear_right_fixed_link">
    <inertial>
      <mass value="0.01"/>
      <inertia ixx="0.001" ixy="0" ixz="0" iyy="0.001" iyz="0" izz="0.001"/>
    </inertial>
  </link>

  <!-- ==================== Wheels (with proper rotation to stand upright) ==================== -->
  <!-- Front Left Wheel -->
  <joint name="front_left_joint" type="continuous">
    <parent link="left_steering_link"/>
    <child link="front_left_wheel"/>
    <origin xyz="0 0 ${-wheel_radius + 0.02}" rpy="0 0 0"/>
    <axis xyz="0 1 0"/>
    <dynamics damping="0.01" friction="0.01"/>
  </joint>
  <link name="front_left_wheel">
    <inertial>
      <mass value="0.5"/>
      <inertia ixx="0.0002" ixy="0" ixz="0" iyy="0.0002" iyz="0" izz="0.0002"/>
    </inertial>
    <visual name="front_left_wheel_visual">
      <origin xyz="0 0 0" rpy="${PI/2} 0 0"/>
      <geometry>
        <cylinder radius="${wheel_radius}" length="${wheel_width}"/>
      </geometry>
      <material name="black">
        <color rgba="0.1 0.1 0.1 1.0"/>
      </material>
    </visual>
    <collision name="front_left_wheel_collision">
      <origin xyz="0 0 0" rpy="${PI/2} 0 0"/>
      <geometry>
        <cylinder radius="${wheel_radius}" length="${wheel_width}"/>
      </geometry>
      <surface>
        <friction>
          <ode>
            <mu>2.0</mu>
            <mu2>2.0</mu2>
          </ode>
        </friction>
      </surface>
    </collision>
  </link>

  <!-- Front Right Wheel -->
  <joint name="front_right_joint" type="continuous">
    <parent link="right_steering_link"/>
    <child link="front_right_wheel"/>
    <origin xyz="0 0 ${-wheel_radius + 0.02}" rpy="0 0 0"/>
    <axis xyz="0 1 0"/>
    <dynamics damping="0.01" friction="0.01"/>
  </joint>
  <link name="front_right_wheel">
    <inertial>
      <mass value="0.5"/>
      <inertia ixx="0.0002" ixy="0" ixz="0" iyy="0.0002" iyz="0" izz="0.0002"/>
    </inertial>
    <visual name="front_right_wheel_visual">
      <origin xyz="0 0 0" rpy="${PI/2} 0 0"/>
      <geometry>
        <cylinder radius="${wheel_radius}" length="${wheel_width}"/>
      </geometry>
      <material name="black">
        <color rgba="0.1 0.1 0.1 1.0"/>
      </material>
    </visual>
    <collision name="front_right_wheel_collision">
      <origin xyz="0 0 0" rpy="${PI/2} 0 0"/>
      <geometry>
        <cylinder radius="${wheel_radius}" length="${wheel_width}"/>
      </geometry>
      <surface>
        <friction>
          <ode>
            <mu>2.0</mu>
            <mu2>2.0</mu2>
          </ode>
        </friction>
      </surface>
    </collision>
  </link>

  <!-- Rear Left Wheel -->
  <joint name="rear_left_joint" type="continuous">
    <parent link="rear_left_fixed_link"/>
    <child link="rear_left_wheel"/>
    <origin xyz="0 0 ${-wheel_radius + 0.02}" rpy="0 0 0"/>
    <axis xyz="0 1 0"/>
    <dynamics damping="0.01" friction="0.01"/>
  </joint>
  <link name="rear_left_wheel">
    <inertial>
      <mass value="0.5"/>
      <inertia ixx="0.0002" ixy="0" ixz="0" iyy="0.0002" iyz="0" izz="0.0002"/>
    </inertial>
    <visual name="rear_left_wheel_visual">
      <origin xyz="0 0 0" rpy="${PI/2} 0 0"/>
      <geometry>
        <cylinder radius="${wheel_radius}" length="${wheel_width}"/>
      </geometry>
      <material name="black">
        <color rgba="0.1 0.1 0.1 1.0"/>
      </material>
    </visual>
    <collision name="rear_left_wheel_collision">
      <origin xyz="0 0 0" rpy="${PI/2} 0 0"/>
      <geometry>
        <cylinder radius="${wheel_radius}" length="${wheel_width}"/>
      </geometry>
      <surface>
        <friction>
          <ode>
            <mu>2.0</mu>
            <mu2>2.0</mu2>
          </ode>
        </friction>
      </surface>
    </collision>
  </link>

  <!-- Rear Right Wheel -->
  <joint name="rear_right_joint" type="continuous">
    <parent link="rear_right_fixed_link"/>
    <child link="rear_right_wheel"/>
    <origin xyz="0 0 ${-wheel_radius + 0.02}" rpy="0 0 0"/>
    <axis xyz="0 1 0"/>
    <dynamics damping="0.01" friction="0.01"/>
  </joint>
  <link name="rear_right_wheel">
    <inertial>
      <mass value="0.5"/>
      <inertia ixx="0.0002" ixy="0" ixz="0" iyy="0.0002" iyz="0" izz="0.0002"/>
    </inertial>
    <visual name="rear_right_wheel_visual">
      <origin xyz="0 0 0" rpy="${PI/2} 0 0"/>
      <geometry>
        <cylinder radius="${wheel_radius}" length="${wheel_width}"/>
      </geometry>
      <material name="black">
        <color rgba="0.1 0.1 0.1 1.0"/>
      </material>
    </visual>
    <collision name="rear_right_wheel_collision">
      <origin xyz="0 0 0" rpy="${PI/2} 0 0"/>
      <geometry>
        <cylinder radius="${wheel_radius}" length="${wheel_width}"/>
      </geometry>
      <surface>
        <friction>
          <ode>
            <mu>2.0</mu>
            <mu2>2.0</mu2>
          </ode>
        </friction>
      </surface>
    </collision>
  </link>

  <!-- ==================== Sensor Links ==================== -->
  <joint name="imu_joint" type="fixed">
    <parent link="base_link"/>
    <child link="imu_link"/>
    <origin xyz="0 0 0.08" rpy="0 0 0"/>
  </joint>
  <link name="imu_link"/>

  <joint name="laser_joint" type="fixed">
    <parent link="base_link"/>
    <child link="laser_link"/>
    <origin xyz="0 0 ${lidar_height}" rpy="0 0.524 0"/>
  </joint>
  <link name="laser_link">
    <inertial>
      <mass value="0.001"/>
      <inertia ixx="0.0001" ixy="0" ixz="0" iyy="0.0001" iyz="0" izz="0.0001"/>
    </inertial>
    <visual name="laser_visual">
      <pose>0 0 0 0 1.5708 0</pose>
      <geometry>
        <cylinder radius="0.025" length="0.04"/>
      </geometry>
      <material name="red">
        <color rgba="1 0 0 1"/>
      </material>
    </visual>
    <collision name="laser_collision">
      <pose>0 0 0 0 1.5708 0</pose>
      <geometry>
        <cylinder radius="0.025" length="0.04"/>
      </geometry>
    </collision>
  </link>

  <joint name="gps_joint" type="fixed">
    <parent link="base_link"/>
    <child link="gps_link"/>
    <origin xyz="0 0 0.3" rpy="0 0 0"/>
  </joint>
  <link name="gps_link"/>

  <!-- ==================== Gazebo Plugins ==================== -->
  <gazebo reference="imu_link">
    <sensor type="imu" name="imu_sensor">
      <always_on>1</always_on>
      <update_rate>100</update_rate>
      <plugin name="gazebo_ros_imu" filename="libgazebo_ros_imu_sensor.so">
        <ros>
          <namespace>/robot</namespace>
          <remapping>~/out:=imu/data</remapping>
        </ros>
        <frame_name>imu_link</frame_name>
      </plugin>
    </sensor>
  </gazebo>

  <gazebo reference="laser_link">
    <sensor type="ray" name="velodyne_sensor">
      <always_on>1</always_on>
      <update_rate>10</update_rate>
      <ray>
        <scan>
          <horizontal>
            <samples>360</samples>
            <resolution>1</resolution>
            <min_angle>-3.14159</min_angle>
            <max_angle>3.14159</max_angle>
          </horizontal>
          <vertical>
            <samples>16</samples>
            <resolution>1</resolution>
            <min_angle>-0.2618</min_angle>
            <max_angle>0.2618</max_angle>
          </vertical>
        </scan>
        <range>
          <min>0.1</min>
          <max>100.0</max>
          <resolution>0.01</resolution>
        </range>
      </ray>
      <plugin name="gazebo_ros_ray_sensor" filename="libgazebo_ros_ray_sensor.so">
        <ros>
          <namespace>/robot</namespace>
          <remapping>~/out:=velodyne_points</remapping>
        </ros>
        <output_type>sensor_msgs/PointCloud2</output_type>
        <frame_name>laser_link</frame_name>
      </plugin>
    </sensor>
  </gazebo>

  <gazebo reference="gps_link">
    <sensor type="gps" name="gps_sensor">
      <always_on>1</always_on>
      <update_rate>5</update_rate>
      <plugin name="gazebo_ros_gps" filename="libgazebo_ros_gps_sensor.so">
        <ros>
          <namespace>/robot</namespace>
          <remapping>~/out:=rtk_gps/fix</remapping>
        </ros>
        <frame_name>gps_link</frame_name>
      </plugin>
    </sensor>
  </gazebo>

  <!-- ==================== Ackermann Drive Controller ==================== -->
  <gazebo>
    <plugin name="ackermann_drive_controller" filename="libackermann_drive_controller.so">
      <ros>
        <namespace>/robot</namespace>
      </ros>
      <cmd_vel_topic>cmd_vel</cmd_vel_topic>
      <odom_topic>odom</odom_topic>
      <ground_truth_odom_topic>ground_truth/odom</ground_truth_odom_topic>
      <odom_frame>odom</odom_frame>
      <base_frame>base_footprint</base_frame>

      <left_steering_joint>left_steering_joint</left_steering_joint>
      <right_steering_joint>right_steering_joint</right_steering_joint>
      <rear_left_wheel_joint>rear_left_joint</rear_left_wheel_joint>
      <rear_right_wheel_joint>rear_right_joint</rear_right_wheel_joint>

      <wheelbase>${wheelbase}</wheelbase>
      <track_width>${track_width}</track_width>
      <wheel_radius>${wheel_radius}</wheel_radius>
      <max_steering_angle>0.5236</max_steering_angle>
      <cmd_timeout>0.5</cmd_timeout>
      <update_rate>50.0</update_rate>
      <steering_p>50.0</steering_p>
      <steering_i>0.0</steering_i>
      <steering_d>5.0</steering_d>
      <max_wheel_torque>50.0</max_wheel_torque>
    </plugin>
  </gazebo>

  <!-- ==================== Joint State Publisher ==================== -->
  <gazebo>
    <plugin name="gazebo_ros_joint_state_publisher" filename="libgazebo_ros_joint_state_publisher.so">
      <ros>
        <remapping>joint_states:=/joint_states</remapping>
      </ros>
      <update_rate>50.0</update_rate>
      <joint_name>left_steering_joint</joint_name>
      <joint_name>right_steering_joint</joint_name>
      <joint_name>steering_wheel_joint</joint_name>
      <joint_name>front_left_joint</joint_name>
      <joint_name>front_right_joint</joint_name>
      <joint_name>rear_left_joint</joint_name>
      <joint_name>rear_right_joint</joint_name>
    </plugin>
  </gazebo>

  <gazebo>
    <plugin name="wheel_encoder_front_left" filename="libwheel_encoder.so">
      <joint>front_left_joint</joint>
      <topic>/robot/wheel_encoder/front_left</topic>
      <update_rate>50.0</update_rate>
      <output_type>angular_velocity</output_type>
    </plugin>
  </gazebo>

  <gazebo>
    <plugin name="wheel_encoder_front_right" filename="libwheel_encoder.so">
      <joint>front_right_joint</joint>
      <topic>/robot/wheel_encoder/front_right</topic>
      <update_rate>50.0</update_rate>
      <output_type>angular_velocity</output_type>
    </plugin>
  </gazebo>

  <gazebo>
    <plugin name="wheel_encoder_rear_left" filename="libwheel_encoder.so">
      <joint>rear_left_joint</joint>
      <topic>/robot/wheel_encoder/rear_left</topic>
      <update_rate>50.0</update_rate>
      <output_type>angular_velocity</output_type>
    </plugin>
  </gazebo>

  <gazebo>
    <plugin name="wheel_encoder_rear_right" filename="libwheel_encoder.so">
      <joint>rear_right_joint</joint>
      <topic>/robot/wheel_encoder/rear_right</topic>
      <update_rate>50.0</update_rate>
      <output_type>angular_velocity</output_type>
    </plugin>
  </gazebo>

  <gazebo>
    <plugin name="wheel_encoder_rear_average" filename="libwheel_encoder.so">
      <joint>rear_left_joint</joint>
      <right_joint>rear_right_joint</right_joint>
      <topic>/robot/wheel_encoder/rear_average</topic>
      <update_rate>50.0</update_rate>
      <wheel_radius>${wheel_radius}</wheel_radius>
      <output_type>linear_velocity</output_type>
    </plugin>
  </gazebo>

</robot>
