<?xml version="1.0"?>
<robot xmlns:xacro="http://www.ros.org/wiki/xacro" name="diff_drive_robot">

  <!-- ==================== Constants ==================== -->
  <xacro:property name="PI" value="3.1415926535897931"/>
  <xacro:property name="wheelbase" value="0.45"/>
  <xacro:property name="track_width" value="0.35"/>
  <xacro:property name="wheel_radius" value="0.07"/>
  <xacro:property name="wheel_diameter" value="0.14"/>
  <xacro:property name="wheel_width" value="0.04"/>
  <xacro:property name="chassis_length" value="0.55"/>
  <xacro:property name="chassis_width" value="0.38"/>
  <xacro:property name="chassis_height" value="0.12"/>
  <xacro:property name="lidar_height" value="0.25"/>

  <!-- ==================== Base Link ==================== -->
  <link name="base_footprint"/>

  <joint name="base_footprint_joint" type="fixed">
    <parent link="base_footprint"/>
    <child link="base_link"/>
    <origin xyz="0 0 ${wheel_radius}" rpy="0 0 0"/>
  </joint>

  <link name="base_link">
    <inertial>
      <mass value="15.0"/>
      <inertia ixx="0.5" ixy="0" ixz="0" iyy="0.5" iyz="0" izz="0.5"/>
    </inertial>
    <visual name="base_visual">
      <geometry>
        <box size="${chassis_length} ${chassis_width} ${chassis_height}"/>
      </geometry>
      <material name="blue">
        <color rgba="0.2 0.4 0.8 1.0"/>
      </material>
    </visual>
    <collision name="base_collision">
      <geometry>
        <box size="${chassis_length} ${chassis_width} ${chassis_height}"/>
      </geometry>
    </collision>
  </link>

  <!-- ==================== Wheels ==================== -->
  <xacro:macro name="wheel" params="name x y">
    <joint name="${name}_joint" type="continuous">
      <parent link="base_link"/>
      <child link="${name}_link"/>
      <origin xyz="${x * wheelbase/2} ${y * track_width/2} ${-wheel_radius}" rpy="${PI/2} 0 0"/>
      <axis xyz="0 0 1"/>
      <dynamics damping="0.05" friction="0.1"/>
    </joint>

    <link name="${name}_link">
      <inertial>
        <mass value="0.5"/>
        <inertia ixx="0.0002" ixy="0" ixz="0" iyy="0.0002" iyz="0" izz="0.0002"/>
      </inertial>
      <visual name="${name}_visual">
        <geometry>
          <cylinder radius="${wheel_radius}" length="${wheel_width}"/>
        </geometry>
        <material name="black">
          <color rgba="0.1 0.1 0.1 1.0"/>
        </material>
      </visual>
      <collision name="${name}_collision">
        <geometry>
          <cylinder radius="${wheel_radius}" length="${wheel_width}"/>
        </geometry>
      </collision>
    </link>
  </xacro:macro>

  <xacro:wheel name="front_left" x="1" y="1"/>
  <xacro:wheel name="front_right" x="1" y="-1"/>
  <xacro:wheel name="rear_left" x="-1" y="1"/>
  <xacro:wheel name="rear_right" x="-1" y="-1"/>

  <!-- ==================== Sensor Links ==================== -->
  <joint name="imu_joint" type="fixed">
    <parent link="base_link"/>
    <child link="imu_link"/>
    <origin xyz="0 0 0.08" rpy="0 0 0"/>
  </joint>
  <link name="imu_link"/>

  <joint name="laser_joint" type="fixed">
    <parent link="base_link"/>
    <child link="laser_link"/>
    <origin xyz="0 0 ${lidar_height}" rpy="0 0 0"/>
  </joint>
  <link name="laser_link">
    <inertial>
      <mass value="0.001"/>
      <inertia ixx="0.0001" ixy="0" ixz="0" iyy="0.0001" iyz="0" izz="0.0001"/>
    </inertial>
    <visual name="laser_visual">
      <geometry>
        <cylinder radius="0.025" length="0.04"/>
      </geometry>
      <material name="red">
        <color rgba="1 0 0 1"/>
      </material>
    </visual>
    <collision name="laser_collision">
      <geometry>
        <cylinder radius="0.025" length="0.04"/>
      </geometry>
    </collision>
  </link>

  <joint name="gps_joint" type="fixed">
    <parent link="base_link"/>
    <child link="gps_link"/>
    <origin xyz="0 0 0.3" rpy="0 0 0"/>
  </joint>
  <link name="gps_link"/>

  <!-- ==================== Gazebo Plugins ==================== -->
  <gazebo reference="imu_link">
    <sensor type="imu" name="imu_sensor">
      <plugin name="gazebo_ros_imu" filename="libgazebo_ros_imu_sensor.so">
        <topicName>imu/data</topicName>
        <bodyName>imu_link</bodyName>
        <updateRateHZ>100</updateRateHZ>
      </plugin>
    </sensor>
  </gazebo>

  <gazebo reference="laser_link">
    <sensor type="ray" name="laser_sensor">
      <always_on>1</always_on>
      <update_rate>10</update_rate>
      <ray>
        <scan>
          <horizontal>
            <samples>360</samples>
            <resolution>1</resolution>
            <min_angle>-3.14159</min_angle>
            <max_angle>3.14159</max_angle>
          </horizontal>
        </scan>
        <range>
          <min>0.1</min>
          <max>30.0</max>
          <resolution>0.02</resolution>
        </range>
      </ray>
      <plugin name="gazebo_ros_laser" filename="libgazebo_ros_ray_sensor.so">
        <ros>
          <namespace>/robot</namespace>
          <remapping>~/out:=scan</remapping>
        </ros>
        <frame_name>laser_link</frame_name>
        <output_type>sensor_msgs/LaserScan</output_type>
      </plugin>
    </sensor>
  </gazebo>

  <gazebo reference="gps_link">
    <sensor type="gps" name="gps_sensor">
      <plugin name="gazebo_ros_gps" filename="libgazebo_ros_gps_sensor.so">
        <topicName>gps/fix</topicName>
        <frameName>gps_link</frameName>
      </plugin>
    </sensor>
  </gazebo>

  <gazebo>
    <plugin name="gazebo_ros_diff_drive" filename="libgazebo_ros_diff_drive.so">
      <ros>
        <namespace>/robot</namespace>
      </ros>
      <update_rate>50</update_rate>
      <left_joint>front_left_joint</left_joint>
      <right_joint>front_right_joint</right_joint>
      <wheel_separation>${track_width}</wheel_separation>
      <wheel_diameter>${wheel_diameter}</wheel_diameter>
      <max_wheel_torque>100</max_wheel_torque>
      <max_wheel_acceleration>0.5</max_wheel_acceleration>
      <publish_odom>true</publish_odom>
      <publish_odom_tf>true</publish_odom_tf>
      <publish_wheel_tf>true</publish_wheel_tf>
    </plugin>
  </gazebo>

</robot>
